<?xml version="1.0" ?>
<!-- =================================================================================== -->
<!-- |    This document was autogenerated by xacro from robot.urdf.xacro               | -->
<!-- |    EDITING THIS FILE BY HAND IS NOT RECOMMENDED                                 | -->
<!-- =================================================================================== -->
<robot name="robot">
  <link name="base_link"/>
  <link name="body_link">
    <visual>
      <origin rpy="1.5707963267948966 0 0" xyz="0 0 0"/>
      <material name="grey">
        <color rgba="0.5 0.5 0.5 1"/>
      </material>
      <geometry>
        <mesh filename="package://rover_description/urdf/meshes/rover_base.stl" scale="0.001 0.001 0.001"/>
      </geometry>
    </visual>
    <collision>
      <origin rpy="1.5707963267948966 0 0" xyz="0 0 0"/>
      <geometry>
        <mesh filename="package://rover_description/urdf/meshes/rover_base.stl" scale="0.001 0.001 0.001"/>
      </geometry>
    </collision>
    <inertial>
      <origin rpy="0 0 0" xyz="0 0 0"/>
      <mass value="2.0"/>
      <inertia ixx="0.1" ixy="0.0" ixz="0.0" iyy="0.1" iyz="0.0" izz="0.1"/>
    </inertial>
  </link>
  <joint name="body_joint" type="fixed">
    <parent link="base_link"/>
    <child link="body_link"/>
    <origin rpy="0 0 0" xyz="0 0 0"/>
  </joint>
  <link name="back_left_wheel_link">
    <visual>
      <origin rpy="1.5707963267948966 0 1.5707963267948966" xyz="0 0 0"/>
      <material name="back">
        <color rgba="0 0 0 1"/>
      </material>
      <geometry>
        <cylinder length="0.026" radius="0.034"/>
      </geometry>
    </visual>
    <collision>
      <origin rpy="1.5707963267948966 0 1.5707963267948966" xyz="0 0 0"/>
      <geometry>
        <cylinder length="0.026" radius="0.034"/>
      </geometry>
    </collision>
    <inertial>
      <origin rpy="1.5707963267948966 0 1.5707963267948966" xyz="0 0 0"/>
      <mass value="0.05"/>
      <inertia ixx="0.0001" ixy="0.0" ixz="0.0" iyy="0.0001" iyz="0.0" izz="0.0001"/>
    </inertial>
  </link>
  <joint name="back_left_wheel_joint" type="continuous">
    <parent link="body_link"/>
    <child link="back_left_wheel_link"/>
    <origin rpy="0 0 3.141592653589793" xyz="-0.085 -0.070718 0.018845"/>
    <axis xyz="1 0 0"/>
  </joint>
  <!-- ================= BACK RIGHT WHEEL ================= -->
  <link name="back_right_wheel_link">
    <visual>
      <origin rpy="1.5707963267948966 0 1.5707963267948966" xyz="0 0 0"/>
      <material name="back">
        <color rgba="0 0 0 1"/>
      </material>
      <geometry>
        <cylinder length="0.026" radius="0.034"/>
      </geometry>
    </visual>
    <collision>
      <origin rpy="1.5707963267948966 0 1.5707963267948966" xyz="0 0 0"/>
      <geometry>
        <cylinder length="0.026" radius="0.034"/>
      </geometry>
    </collision>
    <inertial>
      <origin rpy="1.5707963267948966 0 1.5707963267948966" xyz="0 0 0"/>
      <mass value="0.05"/>
      <inertia ixx="0.0001" ixy="0.0" ixz="0.0" iyy="0.0001" iyz="0.0" izz="0.0001"/>
    </inertial>
  </link>
  <joint name="back_right_wheel_joint" type="continuous">
    <parent link="body_link"/>
    <child link="back_right_wheel_link"/>
    <origin rpy="0 0 0" xyz="0.085 -0.070718 0.018845"/>
    <axis xyz="1 0 0"/>
  </joint>
  <!-- ================= FRONT LEFT WHEEL ================= -->
  <link name="front_left_wheel_link">
    <visual>
      <origin rpy="-1.5707963267948966 0 1.5707963267948966" xyz="0 0 0"/>
      <material name="back">
        <color rgba="0 0 0 1"/>
      </material>
      <geometry>
        <cylinder length="0.026" radius="0.034"/>
      </geometry>
    </visual>
    <collision>
      <origin rpy="1.5707963267948966 0 1.5707963267948966" xyz="0 0 0"/>
      <geometry>
        <cylinder length="0.026" radius="0.034"/>
      </geometry>
    </collision>
    <inertial>
      <origin rpy="1.5707963267948966 0 1.5707963267948966" xyz="0 0 0"/>
      <mass value="0.05"/>
      <inertia ixx="0.0001" ixy="0.0" ixz="0.0" iyy="0.0001" iyz="0.0" izz="0.0001"/>
    </inertial>
  </link>
  <joint name="front_left_wheel_joint" type="continuous">
    <parent link="body_link"/>
    <child link="front_left_wheel_link"/>
    <origin rpy="0 0 3.141592653589793" xyz="-0.085 0.038782 0.018845"/>
    <axis xyz="1 0 0"/>
  </joint>
  <!-- ================= FRONT RIGHT WHEEL ================= -->
  <link name="front_right_wheel_link">
    <visual>
      <origin rpy="1.5707963267948966 0 1.5707963267948966" xyz="0 0 0"/>
      <material name="black">
        <color rgba="0 0 0 1"/>
      </material>
      <geometry>
        <cylinder length="0.026" radius="0.034"/>
      </geometry>
    </visual>
    <collision>
      <origin rpy="1.5707963267948966 0 1.5707963267948966" xyz="0 0 0"/>
      <geometry>
        <cylinder length="0.026" radius="0.034"/>
      </geometry>
    </collision>
    <inertial>
      <origin rpy="1.5707963267948966 0 1.5707963267948966" xyz="0 0 0"/>
      <mass value="0.05"/>
      <inertia ixx="0.0001" ixy="0.0" ixz="0.0" iyy="0.0001" iyz="0.0" izz="0.0001"/>
    </inertial>
  </link>
  <joint name="front_right_wheel_joint" type="continuous">
    <parent link="body_link"/>
    <child link="front_right_wheel_link"/>
    <origin rpy="0 0 0" xyz="0.085 0.038782 0.018845"/>
    <axis xyz="1 0 0"/>
  </joint>
</robot>
